Workbook

Sheet   Journal de Bord des Arrêts
A1: Site | B1: Bâtiment | C1: Date | D1: Semaine | E1: Mois | F1: Année | G1: Demandeur | H1: Équipe | I1: Processus | J1: Poste/Machine | K1: Client | L1: Le reste | M1: Référence | N1: Heure début | O1: Heure fin | P1: Durée en :H | Q1: Nbr d'équipe | R1: Lien | S1: Impact Productivité par client | T1: Sous-Famille Précise | U1: Description | V1: Service | W1: Traité par | X1: Validé par
A2: TEMARA | B2: TEM | C2: 45996 | D2: =YEAR(C2)&"-S"&WEEKNUM(C2) -> 2025-S49 | E2: =YEAR(C2)&"-M"&MONTH(C2) -> 2025-M12 | F2: =YEAR(C2) -> 2025 | G2: DAHAB | H2: NORMALE | I2: FERMETURE ULTRASON | J2: T4662-01 | K2: ABB | L2: ABB | M2: 5001 | N2: 0.5 | O2: 0.75 | P2: =(O2-N2)*24 -> 6 | Q2: 1 | R2: =Q2&L2&A2 -> 1ABBTEMARA | S2: =IF(P2="","",P2/VLOOKUP(R2,'Matrice Productivité '!I:J,2,FALSE)/100) -> 0.010455206 | T2: Défaut d'aspect / Finition | U2: Excès de bavure | V2: MAINTENANCE | W2: NAOUFEL
A3: TEMARA | B3: TEM | C3: 45999 | D3: =YEAR(C3)&"-S"&WEEKNUM(C3) -> 2025-S50 | E3: =YEAR(C3)&"-M"&MONTH(C3) -> 2025-M12 | F3: =YEAR(C3) -> 2025 | G3: DAHAB | H3: NORMALE | I3: FERMETURE ULTRASON | J3: T4662-01 | K3: ABB | L3: ABB | M3: 5012 | N3: 0.35416667 | O3: 0.6875 | P3: =(O3-N3)*24 -> 8 | Q3: 1 | R3: =Q3&L3&A3 -> 1ABBTEMARA | S3: =IF(P3="","",P3/VLOOKUP(R3,'Matrice Productivité '!I:J,2,FALSE)/100) -> 0.013940275 | T3: Non-conformité structurelle | U3: Fissure | V3: MAINTENANCE | W3: NAOUFEL
A4: TEMARA | B4: TEM | C4: 46002 | D4: =YEAR(C4)&"-S"&WEEKNUM(C4) -> 2025-S50 | E4: =YEAR(C4)&"-M"&MONTH(C4) -> 2025-M12 | F4: =YEAR(C4) -> 2025 | G4: SAMIRA | H4: NORMALE | I4: SERTISSAGE GROSSE SECTION | J4: Pince hudraulique TR1462 T 402 | K4: LECLANCHÉ | L4: LECLANCHÉ | M4: LEC0000088 | N4: 0.41666667 | O4: 0.625 | P4: =(O4-N4)*24 -> 5 | Q4: 1 | R4: =Q4&L4&A4 -> 1LECLANCHÉTEMARA | S4: =IF(P4="","",P4/VLOOKUP(R4,'Matrice Productivité '!I:J,2,FALSE)/100) -> 0.0041592591 | T4: Casse mécanique sur produit | U4: Tige de verrouillage cassée | V4: MAINTENANCE | W4: NAOUFEL
A5: TEMARA | B5: TEM | C5: 46003 | D5: =YEAR(C5)&"-S"&WEEKNUM(C5) -> 2025-S50 | E5: =YEAR(C5)&"-M"&MONTH(C5) -> 2025-M12 | F5: =YEAR(C5) -> 2025 | G5: DAHAB | H5: NORMALE | I5: FERMETURE ULTRASON | J5: T4662-01 | K5: ABB | L5: ABB | M5: 5012 | N5: 0.45833333 | O5: 0.5 | P5: =(O5-N5)*24 -> 1 | Q5: 1 | R5: =Q5&L5&A5 -> 1ABBTEMARA | S5: =IF(P5="","",P5/VLOOKUP(R5,'Matrice Productivité '!I:J,2,FALSE)/100) -> 0.0017425344 | T5: Non-conformité structurelle | U5: Fissure | V5: MAINTENANCE | W5: NAOUFEL
A6: TEMARA | B6: TEM | C6: 46006 | D6: =YEAR(C6)&"-S"&WEEKNUM(C6) -> 2025-S51 | E6: =YEAR(C6)&"-M"&MONTH(C6) -> 2025-M12 | F6: =YEAR(C6) -> 2025 | G6: ANAS | H6: NORMALE | I6: TEST | J6: T5008-19 | K6: IES | L6: LE RESTE | M6: Tower | N6: 0.51388889 | O6: 0.72916667 | P6: =(O6-N6)*24 -> 5.1666667 | Q6: 1 | R6: =Q6&L6&A6 -> 1LE RESTETEMARA | S6: =IF(P6="","",P6/VLOOKUP(R6,'Matrice Productivité '!I:J,2,FALSE)/100) -> 0.011202471 | T6: Interruption flux opératoire | U6: Blocage à l'étape Carte module | V6: TECHNIQUE | W6: NAOUFAL + PAUL
A7: TEMARA | B7: TEM | C7: 46007 | D7: =YEAR(C7)&"-S"&WEEKNUM(C7) -> 2025-S51 | E7: =YEAR(C7)&"-M"&MONTH(C7) -> 2025-M12 | F7: =YEAR(C7) -> 2025 | G7: DAHAB | H7: NORMALE | I7: FERMETURE ULTRASON | J7: T4662-01 | K7: ABB | L7: ABB | M7: 5005 | N7: 0.38541667 | O7: 0.42708333 | P7: =(O7-N7)*24 -> 1 | Q7: 1 | R7: =Q7&L7&A7 -> 1ABBTEMARA | S7: =IF(P7="","",P7/VLOOKUP(R7,'Matrice Productivité '!I:J,2,FALSE)/100) -> 0.0017425344 | T7: Mauvais plaquage ABB | U7: Défaut de plaquage du plaquage | V7: MAINTENANCE | W7: NAOUFEL
A8: TEMARA | B8: TEM | C8: 46009 | D8: =YEAR(C8)&"-S"&WEEKNUM(C8) -> 2025-S51 | E8: =YEAR(C8)&"-M"&MONTH(C8) -> 2025-M12 | F8: =YEAR(C8) -> 2025 | G8: ANAS | H8: NORMALE | I8: TEST | J8: T5008-19 | K8: IES | L8: LE RESTE | M8: Tower | N8: 0.375 | O8: 0.45833333 | P8: =(O8-N8)*24 -> 2 | Q8: 1 | R8: =Q8&L8&A8 -> 1LE RESTETEMARA | S8: =IF(P8="","",P8/VLOOKUP(R8,'Matrice Productivité '!I:J,2,FALSE)/100) -> 0.0043364405 | T8: Interruption flux opératoire | U8: Blocage à l'étape Carte module | V8: TECHNIQUE | W8: ABDELLAH/ANAS
A9: TEMARA | B9: TEM | C9: 46010 | D9: =YEAR(C9)&"-S"&WEEKNUM(C9) -> 2025-S51 | E9: =YEAR(C9)&"-M"&MONTH(C9) -> 2025-M12 | F9: =YEAR(C9) -> 2025 | G9: DAHAB | H9: NORMALE | I9: TEST | J9: PO70032 | K9: ABB | L9: ABB | M9: 5018 | N9: 0.42013889 | O9: 0.66666667 | P9: =(O9-N9)*24 -> 5.9166667 | Q9: 1 | R9: =Q9&L9&A9 -> 1ABBTEMARA | S9: =IF(P9="","",P9/VLOOKUP(R9,'Matrice Productivité '!I:J,2,FALSE)/100) -> 0.010309995 | T9: Blocage accès logiciel | U9: Problème du mot de passe | V9: IT | W9: KARIM
A10: TEMARA | B10: TEM | C10: 46013 | D10: =YEAR(C10)&"-S"&WEEKNUM(C10) -> 2025-S52 | E10: =YEAR(C10)&"-M"&MONTH(C10) -> 2025-M12 | F10: =YEAR(C10) -> 2025 | G10: DAHAB | H10: NORMALE | I10: FERMETURE ULTRASON | J10: T4662-01 | K10: ABB | L10: ABB | M10: 5036 | N10: 0.63194444 | O10: 0.65486111 | P10: =(O10-N10)*24 -> 0.55 | Q10: 1 | R10: =Q10&L10&A10 -> 1ABBTEMARA | S10: =IF(P10="","",P10/VLOOKUP(R10,'Matrice Productivité '!I:J,2,FALSE)/100) -> 0.0009583939 | T10: Mauvais plaquage ABB | U10: Problème du plaquage | V10: MAINTENANCE | W10: NAOUFEL
A11: TEMARA | B11: TEM | C11: 46013 | D11: =YEAR(C11)&"-S"&WEEKNUM(C11) -> 2025-S52 | E11: =YEAR(C11)&"-M"&MONTH(C11) -> 2025-M12 | F11: =YEAR(C11) -> 2025 | G11: DAHAB | H11: NORMALE | I11: TAMPOGRAPHIE | J11: T4680-01 | K11: ABB | L11: ABB | M11: 5040 | N11: 0.59027778 | O11: 0.65277778 | P11: =(O11-N11)*24 -> 1.5 | Q11: 1 | R11: =Q11&L11&A11 -> 1ABBTEMARA | S11: =IF(P11="","",P11/VLOOKUP(R11,'Matrice Productivité '!I:J,2,FALSE)/100) -> 0.0026138015 | T11: Usure / Dégradation outillage | U11: Taraudage foiré du support cliché | V11: MAINTENANCE | W11: NAOUFEL
A12: TEMARA | B12: TEM | C12: 46013 | D12: =YEAR(C12)&"-S"&WEEKNUM(C12) -> 2025-S52 | E12: =YEAR(C12)&"-M"&MONTH(C12) -> 2025-M12 | F12: =YEAR(C12) -> 2025 | G12: DAHAB | H12: NORMALE | I12: TEST | J12: PO70032 | K12: ABB | L12: ABB | M12: 5058 | N12: 0.375 | O12: 0.75 | P12: =(O12-N12)*24 -> 9 | Q12: 1 | R12: =Q12&L12&A12 -> 1ABBTEMARA | S12: =IF(P12="","",P12/VLOOKUP(R12,'Matrice Productivité '!I:J,2,FALSE)/100) -> 0.015682809 | T12: Panne matériel informatique | U12: PC banc de test ne s'allume pas | V12: MAINTENANCE | W12: NAOUFEL /MOUJAHID
A13: TEMARA | B13: TEM | C13: 46014 | D13: =YEAR(C13)&"-S"&WEEKNUM(C13) -> 2025-S52 | E13: =YEAR(C13)&"-M"&MONTH(C13) -> 2025-M12 | F13: =YEAR(C13) -> 2025 | G13: DAHAB | H13: NORMALE | I13: TEST | J13: PO70032 | K13: ABB | L13: ABB | M13: 5012 | N13: 0.375 | O13: 0.75 | P13: =(O13-N13)*24 -> 9 | Q13: 1 | R13: =Q13&L13&A13 -> 1ABBTEMARA | S13: =IF(P13="","",P13/VLOOKUP(R13,'Matrice Productivité '!I:J,2,FALSE)/100) -> 0.015682809 | T13: Panne matériel informatique | U13: PC banc de test ne s'allume pas | V13: MAINTENANCE | W13: NAOUFEL /MOUJAHID
A14: TEMARA | B14: TEM | C14: 46014 | D14: =YEAR(C14)&"-S"&WEEKNUM(C14) -> 2025-S52 | E14: =YEAR(C14)&"-M"&MONTH(C14) -> 2025-M12 | F14: =YEAR(C14) -> 2025 | G14: DAHAB | H14: NORMALE | I14: TAMPOGRAPHIE | J14: T4680-01 | K14: ABB | L14: ABB | M14: 5075 | N14: 0.35416667 | O14: 0.52083333 | P14: =(O14-N14)*24 -> 4 | Q14: 1 | R14: =Q14&L14&A14 -> 1ABBTEMARA | S14: =IF(P14="","",P14/VLOOKUP(R14,'Matrice Productivité '!I:J,2,FALSE)/100) -> 0.0069701374 | T14: Usure / Dégradation outillage | U14: Taraudage foiré du support cliché | V14: MAINTENANCE | W14: NAOUFEL
A15: BERRECHID | B15: Bât B | C15: 46014 | D15: =YEAR(C15)&"-S"&WEEKNUM(C15) -> 2025-S52 | E15: =YEAR(C15)&"-M"&MONTH(C15) -> 2025-M12 | F15: =YEAR(C15) -> 2025 | G15: OUMAIMA | H15: MATIN | I15: INTÉGRATION | J15: Intégration 1 | K15: EDMI | L15: EDMI | M15: EDMES030CAD-00 | N15: 0.53472222 | O15: 0.58333333 | P15: =(O15-N15)*24 -> 1.1666667 | Q15: 3 | R15: =Q15&L15&A15 -> 3EDMIBERRECHID | S15: =IF(P15="","",P15/VLOOKUP(R15,'Matrice Productivité '!I:J,2,FALSE)/100) -> 0.00090392562 | T15: Échec lecture / Identification | U15: Pb de scan sur la carte display EDM830-00144 qty 20 cartes Pb de scan sur la carte ICHIS EDM830-00140 qty 85 cartes | V15: TECHNIQUE | W15: ENCOURS DE TRAITEMENT PAR YOUNESS ADAM
A16: BERRECHID | B16: Bât B | C16: 46015 | D16: =YEAR(C16)&"-S"&WEEKNUM(C16) -> 2025-S52 | E16: =YEAR(C16)&"-M"&MONTH(C16) -> 2025-M12 | F16: =YEAR(C16) -> 2025 | G16: OUMAIMA | H16: MATIN | I16: INTÉGRATION | J16: Intégration | K16: EDMI | L16: EDMI | M16: EDMES030CAD-00 | N16: 0.25 | O16: 0.27083333 | P16: =(O16-N16)*24 -> 0.5 | Q16: 3 | R16: =Q16&L16&A16 -> 3EDMIBERRECHID | S16: =IF(P16="","",P16/VLOOKUP(R16,'Matrice Productivité '!I:J,2,FALSE)/100) -> 0.00038739669 | T16: Manque de moyens de travail | U16: Manque de moyens de travail (chariots, chaises, bacs) | V16: TECHNIQUE | W16: DÉPANNAGE
A17: BERRECHID | B17: Bât B | C17: 46015 | D17: =YEAR(C17)&"-S"&WEEKNUM(C17) -> 2025-S52 | E17: =YEAR(C17)&"-M"&MONTH(C17) -> 2025-M12 | F17: =YEAR(C17) -> 2025 | G17: OUMAIMA | H17: MATIN | I17: INTÉGRATION | J17: Intégration 1 | K17: EDMI | L17: EDMI | M17: EDMES030CAD-00 | N17: 0.33333333 | O17: 0.375 | P17: =(O17-N17)*24 -> 1 | Q17: 3 | R17: =Q17&L17&A17 -> 3EDMIBERRECHID | S17: =IF(P17="","",P17/VLOOKUP(R17,'Matrice Productivité '!I:J,2,FALSE)/100) -> 0.00077479339 | T17: Incident édition / Marquage | U17: Manque d'étiquette d'intégration (erreur impression, saut lot) | V17: PRODUCTION | W17: GOTNI
A18: BERRECHID | B18: Bât B | C18: 46015 | D18: =YEAR(C18)&"-S"&WEEKNUM(C18) -> 2025-S52 | E18: =YEAR(C18)&"-M"&MONTH(C18) -> 2025-M12 | F18: =YEAR(C18) -> 2025 | G18: OUMAIMA | H18: MATIN | I18: INTÉGRATION | J18: Dégrappage | K18: EDMI | L18: EDMI | M18: EDMES030CAD-00 | N18: 0.46875 | O18: 0.48263889 | P18: =(O18-N18)*24 -> 0.33333333 | Q18: 3 | R18: =Q18&L18&A18 -> 3EDMIBERRECHID | S18: =IF(P18="","",P18/VLOOKUP(R18,'Matrice Productivité '!I:J,2,FALSE)/100) -> 0.00025826446 | T18: Rupture approvisionnement | U18: Manque de carte display EDM830-00144 (retard transport) | V18: SUPPLY | W18: BOUDRA
A19: BERRECHID | B19: Bât B | C19: 46015 | D19: =YEAR(C19)&"-S"&WEEKNUM(C19) -> 2025-S52 | E19: =YEAR(C19)&"-M"&MONTH(C19) -> 2025-M12 | F19: =YEAR(C19) -> 2025 | G19: OUMAIMA | H19: MATIN | I19: TEST UFT | J19: Test UFT | K19: EDMI | L19: EDMI | M19: EDMS010BXD-10-BRITIS: | N19: 0.47222222 | O19: 0.5 | P19: =(O19-N19)*24 -> 0.66666667 | Q19: 3 | R19: =Q19&L19&A19 -> 3EDMIBERRECHID | S19: =IF(P19="","",P19/VLOOKUP(R19,'Matrice Productivité '!I:J,2,FALSE)/100) -> 0.00051652893 | T19: Réglage technique / Maintenance | U19: Arrêt test UFT suite à l'intervention de service test | V19: TECHNIQUE | W19: AMINE/SAID
A20: BERRECHID | B20: Bât B | C20: 46015 | D20: =YEAR(C20)&"-S"&WEEKNUM(C20) -> 2025-S52 | E20: =YEAR(C20)&"-M"&MONTH(C20) -> 2025-M12 | F20: =YEAR(C20) -> 2025 | G20: TARIK | H20: APM | I20: TEST ICT | J20: Testeur ICT | K20: EDMI | L20: EDMI | M20: EDMES030CAD-00 | N20: 0.86458333 | O20: 0.89583333 | P20: =(O20-N20)*24 -> 0.75 | Q20: 3 | R20: =Q20&L20&A20 -> 3EDMIBERRECHID | S20: =IF(P20="","",P20/VLOOKUP(R20,'Matrice Productivité '!I:J,2,FALSE)/100) -> 0.00058109504 | T20: Conflit interface de test | U20: Pb lors du passage de la réf EDM830-00144 à l'ICT (interface) | V20: TECHNIQUE | W20: SAID
A21: BERRECHID | B21: Bât A | C21: 46015 | D21: =YEAR(C21)&"-S"&WEEKNUM(C21) -> 2025-S52 | E21: =YEAR(C21)&"-M"&MONTH(C21) -> 2025-M12 | F21: =YEAR(C21) -> 2025 | G21: ISMAIL | H21: APM | I21: TEST | J21: TAKAYA-9400 | K21: EMS | L21: EMS | M21: EMS-156 | N21: 0.66666667 | O21: 0.6875 | P21: =(O21-N21)*24 -> 0.5 | Q21: 2 | R21: =Q21&L21&A21 -> 2EMSBERRECHID | S21: =IF(P21="","",P21/VLOOKUP(R21,'Matrice Productivité '!I:J,2,FALSE)/100) -> 9.2975207e-05 | T21: Défaillance électrique banc de test | U21: Prob Relay on-test | V21: MAINTENANCE | W21: SLIMANE
A22: BERRECHID | B22: Bât A | C22: 46015 | D22: =YEAR(C22)&"-S"&WEEKNUM(C22) -> 2025-S52 | E22: =YEAR(C22)&"-M"&MONTH(C22) -> 2025-M12 | F22: =YEAR(C22) -> 2025 | G22: ISMAIL | H22: APM | I22: TEST | J22: TAKAYA-9400 | K22: EMS | L22: EMS | M22: EMS-167 | N22: 0.83333333 | O22: 0.86111111 | P22: =(O22-N22)*24 -> 0.66666667 | Q22: 2 | R22: =Q22&L22&A22 -> 2EMSBERRECHID | S22: =IF(P22="","",P22/VLOOKUP(R22,'Matrice Productivité '!I:J,2,FALSE)/100) -> 0.00012396694 | T22: Bug logiciel machine CMS | U22: Bug de la machine Takaya-9400 | V22: MAINTENANCE | W22: INTERVENTION A DISTANCE ( ISMAIL )
A23: BERRECHID | B23: Bât A | C23: 46016 | D23: =YEAR(C23)&"-S"&WEEKNUM(C23) -> 2025-S52 | E23: =YEAR(C23)&"-M"&MONTH(C23) -> 2025-M12 | F23: =YEAR(C23) -> 2025 | G23: ISMAIL | H23: MATIN | I23: TEST | J23: Test Fonctionnel | K23: MERCK | L23: LE RESTE | M23: MEMMERPF08040 | N23: 0.49305556 | O23: 0.75 | P23: =(O23-N23)*24 -> 6.1666667 | Q23: 2 | R23: =Q23&L23&A23 -> 2LE RESTEBERRECHID | S23: =IF(P23="","",P23/VLOOKUP(R23,'Matrice Productivité '!I:J,2,FALSE)/100) -> 0.0023889463 | T23: Dérive process (Nettoyage) | U23: Détection de 4 cartes successives en défaut (Index : 47) | V23: TECHNIQUE | W23: INTERVENTION DE ( SAID + ISMAIL : VALIDATION DE ADEL )
A24: BERRECHID | B24: Bât B | C24: 46017 | D24: =YEAR(C24)&"-S"&WEEKNUM(C24) -> 2025-S52 | E24: =YEAR(C24)&"-M"&MONTH(C24) -> 2025-M12 | F24: =YEAR(C24) -> 2025 | G24: OUMAIMA | H24: MATIN | I24: INTÉGRATION | J24: intégration | K24: EDMI | L24: EDMI | M24: EDMS010BXD-10-BRITIS: | N24: 0.39583333 | O24: 0.45833333 | P24: =(O24-N24)*24 -> 1.5 | Q24: 3 | R24: =Q24&L24&A24 -> 3EDMIBERRECHID | S24: =IF(P24="","",P24/VLOOKUP(R24,'Matrice Productivité '!I:J,2,FALSE)/100) -> 0.0011621901 | T24: Panne mécanique convoyage | U24: Dysfonctionnement de convoyeur de posage d'intégration | V24: MAINTENANCE | W24: SLIMANE
A25: BERRECHID | B25: Bât A | C25: 46013 | D25: =YEAR(C25)&"-S"&WEEKNUM(C25) -> 2025-S52 | E25: =YEAR(C25)&"-M"&MONTH(C25) -> 2025-M12 | F25: =YEAR(C25) -> 2025 | G25: KNIDAR | H25: NUIT | I25: CMS | J25: LIGNE 2 | K25: EDMI | L25: EDMI | M25: EDM830-010-107BRTISH | N25: 0.91666667 | O25: 0.94166667 | P25: =(O25-N25)*24 -> 0.6 | Q25: 3 | R25: =Q25&L25&A25 -> 3EDMIBERRECHID | S25: =IF(P25="","",P25/VLOOKUP(R25,'Matrice Productivité '!I:J,2,FALSE)/100) -> 0.00046487603 | T25: Changement de série (Setup) | U25: Recherche Bobine + chargement (Mq Séquenceur) | V25: SUPPLY | W25: AYOUB
A26: BERRECHID | B26: Bât A | C26: 46013 | D26: =YEAR(C26)&"-S"&WEEKNUM(C26) -> 2025-S52 | E26: =YEAR(C26)&"-M"&MONTH(C26) -> 2025-M12 | F26: =YEAR(C26) -> 2025 | G26: KNIDAR | H26: APM | I26: CMS | J26: LIGNE 2 | K26: EDMI | L26: EDMI | M26: EDM830-010-107BRTISH | N26: 0.58333333 | O26: 0.60833333 | P26: =(O26-N26)*24 -> 0.6 | Q26: 3 | R26: =Q26&L26&A26 -> 3EDMIBERRECHID | S26: =IF(P26="","",P26/VLOOKUP(R26,'Matrice Productivité '!I:J,2,FALSE)/100) -> 0.00046487603 | T26: Changement de série (Setup) | U26: Recherche Bobine + chargement (Manque séquenceur) | V26: SUPPLY | W26: MEHDI
... A63: BERRECHID | B63: Bât B | C63: 46022 | D63: =YEAR(C63)&"-S"&WEEKNUM(C63) -> 2025-S53 | E63: =YEAR(C63)&"-M"&MONTH(C63) -> 2025-M12 | F63: =YEAR(C63) -> 2025 | G63: OUMAIMA | H63: NUIT | I63: TEST BFT | J63: Testeur BFT | K63: EDMI | L63: EDMI | M63: EDM830-013-152 | N63: 0.083333333 | O63: 0.13166667 | P63: =(O63-N63)*24 -> 1.16 | Q63: 3 | R63: =Q63&L63&A63 -> 3EDMIBERRECHID | S63: =IF(P63="","",P63/VLOOKUP(R63,'Matrice Productivité '!I:J,2,FALSE)/100) -> 0.00089876033 | T63: Panne applicative banc | U63: Disfonctionnement de (tester application SUFT) | V63: TECHNIQUE | W63: SAID+AMINE
A64: BERRECHID | B64: Bât A | C64: 46021 | D64: =YEAR(C64)&"-S"&WEEKNUM(C64) -> 2025-S53 | E64: =YEAR(C64)&"-M"&MONTH(C64) -> 2025-M12 | F64: =YEAR(C64) -> 2025 | G64: KNIDAR | H64: NUIT | I64: CMS | J64: LIGNE 2 | K64: EDMI | L64: EDMI | M64: EDM830-010-107BRTISH | N64: 0.91666667 | O64: 0.079166667 | P64: =(O64-N64)*24+24 -> 3.9 | Q64: 3 | R64: =Q64&L64&A64 -> 3EDMIBERRECHID | S64: =IF(P64="","",P64/VLOOKUP(R64,'Matrice Productivité '!I:J,2,FALSE)/100) -> 0.0030216942 | T64: Changement de série (Setup) | U64: Set-up ligne ES10 + recherche bobines | V64: SUPPLY | W64: AYOUB
A65: BERRECHID | B65: Bât A | C65: 46021 | D65: =YEAR(C65)&"-S"&WEEKNUM(C65) -> 2025-S53 | E65: =YEAR(C65)&"-M"&MONTH(C65) -> 2025-M12 | F65: =YEAR(C65) -> 2025 | G65: KNIDAR | H65: MATIN | I65: CMS | J65: LIGNE 2 | K65: EDMI | L65: EDMI | M65: EDM830-010-107BRTISH | N65: 0.25 | O65: 0.34722222 | P65: =(O65-N65)*24 -> 2.3333333 | Q65: 3 | R65: =Q65&L65&A65 -> 3EDMIBERRECHID | S65: =IF(P65="","",P65/VLOOKUP(R65,'Matrice Productivité '!I:J,2,FALSE)/100) -> 0.0018078512 | T65: Lancement Nouvelle Réf (Validation) | U65: Validation ES10 + recherche bobines | V65: TECHNIQUE | W65: BRAHIM
A66: BERRECHID | B66: Bât A | C66: 46021 | D66: =YEAR(C66)&"-S"&WEEKNUM(C66) -> 2025-S53 | E66: =YEAR(C66)&"-M"&MONTH(C66) -> 2025-M12 | F66: =YEAR(C66) -> 2025 | G66: KNIDAR | H66: APM | I66: CMS | J66: LIGNE 2 | K66: EDMI | L66: EDMI | M66: EDM830-010-107BRTISH | N66: 0.58333333 | O66: 0.60069444 | P66: =(O66-N66)*24 -> 0.41666667 | Q66: 3 | R66: =Q66&L66&A66 -> 3EDMIBERRECHID | S66: =IF(P66="","",P66/VLOOKUP(R66,'Matrice Productivité '!I:J,2,FALSE)/100) -> 0.00032283058 | T66: Changement de série (Setup) | U66: Recherche et changement bobines | V66: SUPPLY | W66: MEHDI
A67: BERRECHID | B67: Bât A | C67: 46022 | D67: =YEAR(C67)&"-S"&WEEKNUM(C67) -> 2025-S53 | E67: =YEAR(C67)&"-M"&MONTH(C67) -> 2025-M12 | F67: =YEAR(C67) -> 2025 | G67: KNIDAR | H67: NUIT | I67: CMS | J67: LIGNE 2 | K67: EDMI | L67: EDMI | M67: EDM830-010-107BRTISH | N67: 0.91666667 | O67: 0.96180556 | P67: =(O67-N67)*24 -> 1.0833333 | Q67: 3 | R67: =Q67&L67&A67 -> 3EDMIBERRECHID | S67: =IF(P67="","",P67/VLOOKUP(R67,'Matrice Productivité '!I:J,2,FALSE)/100) -> 0.0008393595 | T67: Changement de série (Setup) | U67: Recherche et changement bobines | V67: SUPPLY | W67: AYOUB
A68: BERRECHID | B68: Bât A | C68: 46022 | D68: =YEAR(C68)&"-S"&WEEKNUM(C68) -> 2025-S53 | E68: =YEAR(C68)&"-M"&MONTH(C68) -> 2025-M12 | F68: =YEAR(C68) -> 2025 | G68: KHADIM | H68: MATIN | I68: CMS | J68: LIGNE 1 | K68: SERAP | L68: LE RESTE | M68: SERRL5B | N68: 0.25 | O68: 0.33333333 | P68: =(O68-N68)*24 -> 2 | Q68: 2 | R68: =Q68&L68&A68 -> 2LE RESTEBERRECHID | S68: =IF(P68="","",P68/VLOOKUP(R68,'Matrice Productivité '!I:J,2,FALSE)/100) -> 0.00077479339 | T68: Incident mécanique machine | U68: Blocage du support des tables 3 et 4 | V68: MAINTENANCE | W68: ABDELHAMID
A69: BERRECHID | B69: Bât A | C69: 46022 | D69: =YEAR(C69)&"-S"&WEEKNUM(C69) -> 2025-S53 | E69: =YEAR(C69)&"-M"&MONTH(C69) -> 2025-M12 | F69: =YEAR(C69) -> 2025 | G69: KNIDAR | H69: MATIN | I69: CMS | J69: LIGNE 2 | K69: EDMI | L69: EDMI | M69: EDM830-010-107BRTISH | N69: 0.25 | O69: 0.30208333 | P69: =(O69-N69)*24 -> 1.25 | Q69: 3 | R69: =Q69&L69&A69 -> 3EDMIBERRECHID | S69: =IF(P69="","",P69/VLOOKUP(R69,'Matrice Productivité '!I:J,2,FALSE)/100) -> 0.00096849174 | T69: Changement de série (Setup) | U69: Recherche et changement bobines | V69: SUPPLY | W69: DRISS
A70: BERRECHID | B70: Bât B | C70: 46022 | D70: =YEAR(C70)&"-S"&WEEKNUM(C70) -> 2025-S53 | E70: =YEAR(C70)&"-M"&MONTH(C70) -> 2025-M12 | F70: =YEAR(C70) -> 2025 | G70: TARIK | H70: MATIN | I70: FINITION | J70: finition 1/2 | K70: EDMI | L70: EDMI | M70: EDM830-013-152 | N70: 0.35763889 | O70: 0.43055556 | P70: =(O70-N70)*24 -> 1.75 | Q70: 3 | R70: =Q70&L70&A70 -> 3EDMIBERRECHID | S70: =IF(P70="","",P70/VLOOKUP(R70,'Matrice Productivité '!I:J,2,FALSE)/100) -> 0.0013558884 | T70: Rupture approvisionnement | U70: Manque des PCB ES-12B | V70: SUPPLY | W70: ABOUDA
A71: BERRECHID | B71: Bât B | C71: 46022 | D71: =YEAR(C71)&"-S"&WEEKNUM(C71) -> 2025-S53 | E71: =YEAR(C71)&"-M"&MONTH(C71) -> 2025-M12 | F71: =YEAR(C71) -> 2025 | G71: TARIK | H71: MATIN | I71: TESTEUR BFT | J71: Testeur BFT | K71: EDMI | L71: EDMI | M71: EDM830-013-152 | N71: 0.25 | O71: 0.34375 | P71: =(O71-N71)*24 -> 2.25 | Q71: 3 | R71: =Q71&L71&A71 -> 3EDMIBERRECHID | S71: =IF(P71="","",P71/VLOOKUP(R71,'Matrice Productivité '!I:J,2,FALSE)/100) -> 0.0017432851 | T71: Temps mort / Attente expert | U71: Attente service technique | V71: TECHNIQUE | W71: SAID
A72: BERRECHID | B72: Bât B | C72: 46022 | D72: =YEAR(C72)&"-S"&WEEKNUM(C72) -> 2025-S53 | E72: =YEAR(C72)&"-M"&MONTH(C72) -> 2025-M12 | F72: =YEAR(C72) -> 2025 | G72: TARIK | H72: MATIN | I72: INTEGRATION | J72: integration | K72: EDMI | L72: EDMI | M72: EDMES012BAD-02 | N72: 0.25 | O72: 0.35416667 | P72: =(O72-N72)*24 -> 2.5 | Q72: 3 | R72: =Q72&L72&A72 -> 3EDMIBERRECHID | S72: =IF(P72="","",P72/VLOOKUP(R72,'Matrice Productivité '!I:J,2,FALSE)/100) -> 0.0019369835 | T72: Goulot d'étranglement test | U72: Attente BFT | V72: TECHNIQUE | W72: SAID
A73: BERRECHID | B73: Bât A | C73: 46022 | D73: =YEAR(C73)&"-S"&WEEKNUM(C73) -> 2025-S53 | E73: =YEAR(C73)&"-M"&MONTH(C73) -> 2025-M12 | F73: =YEAR(C73) -> 2025 | G73: ISMAIL | H73: MATIN | I73: TEST TAKAYA | J73: Takaya-9411 | K73: EMS | L73: EMS | M73: EMSEJ-244 | N73: 0.35416667 | O73: 0.41666667 | P73: =(O73-N73)*24 -> 1.5 | Q73: 2 | R73: =Q73&L73&A73 -> 2EMSBERRECHID | S73: =IF(P73="","",P73/VLOOKUP(R73,'Matrice Productivité '!I:J,2,FALSE)/100) -> 0.00027892562 | T73: Instabilité matériel (Pointes) | U73: Taux faux défaut élevé lié au probe 3 | V73: MAINTENANCE | W73: SLIMANE
A74: BERRECHID | B74: Bât B | C74: 46022 | D74: =YEAR(C74)&"-S"&WEEKNUM(C74) -> 2025-S53 | E74: =YEAR(C74)&"-M"&MONTH(C74) -> 2025-M12 | F74: =YEAR(C74) -> 2025 | G74: TARIK | H74: MATIN | I74: TEST ICT | J74: Testeur ICT | K74: EDMI | L74: EDMI | M74: EDM830-013-152 | N74: 0.38888889 | O74: 0.45833333 | P74: =(O74-N74)*24 -> 1.6666667 | Q74: 3 | R74: =Q74&L74&A74 -> 3EDMIBERRECHID | S74: =IF(P74="","",P74/VLOOKUP(R74,'Matrice Productivité '!I:J,2,FALSE)/100) -> 0.0012913223 | T74: Mise au point logicielle | U74: Débogage programme ICT | V74: TECHNIQUE | W74: SAID
A75: BERRECHID | B75: Bât A | C75: 46022 | D75: =YEAR(C75)&"-S"&WEEKNUM(C75) -> 2025-S53 | E75: =YEAR(C75)&"-M"&MONTH(C75) -> 2025-M12 | F75: =YEAR(C75) -> 2025 | G75: KNIDAR | H75: APM | I75: CMS | J75: LIGNE 2 | K75: EDMI | L75: EDMI | M75: EDM830-010-107BRTISH | N75: 0.58333333 | O75: 0.63541667 | P75: =(O75-N75)*24 -> 1.25 | Q75: 3 | R75: =Q75&L75&A75 -> 3EDMIBERRECHID | S75: =IF(P75="","",P75/VLOOKUP(R75,'Matrice Productivité '!I:J,2,FALSE)/100) -> 0.00096849174 | T75: Changement de série (Setup) | U75: Recherche composant + changement bobines + déchargement MSL | V75: SUPPLY | W75: ABDERRAHMANE+ZOUHAIR
A76: BERRECHID | B76: Bât B | C76: 46023 | D76: =YEAR(C76)&"-S0"&WEEKNUM(C76) -> 2026-S01 | E76: =YEAR(C76)&"-M0"&MONTH(C76) -> 2026-M01 | F76: =YEAR(C76) -> 2026 | G76: OUMAIMA | H76: NUIT | I76: TEST BFT | J76: Testeur BFT | K76: EDMI | L76: EDMI | M76: EDM830-013-152 | N76: 0.14583333 | O76: 0.25 | P76: =(O76-N76)*24 -> 2.5 | Q76: 3 | R76: =Q76&L76&A76 -> 3EDMIBERRECHID | S76: =IF(P76="","",P76/VLOOKUP(R76,'Matrice Productivité '!I:J,2,FALSE)/100) -> 0.0019369835 | T76: Panne applicative banc | U76: Disfonctionnement de (tester application SUFT) | V76: TECHNIQUE | W76: SAID
...

Sheet Matrice Productivité 
A1: Site | B1: Client | C1: Nbr d'équipe | D1: Temps Gamme Moyen par mois pour le client | E1: Temps de présence mensuel Moyen du site (Tout projet confendu, Témara seule, Berrechid seul) | F1: Poids par client | G1: 0.01 | H1: Temps d'ouverture Moyen/Mois pour 1 Shift | I1: Lien | J1: Temps d'arrêt | P1: =MOD(A2+(B2/24), 1) -> #VALUE! | Q1: =IF(O5="","",(O5-N5)*24)
A2: Temara | B2: ABB | C2: 1 | D2: 2321 | E2: =43*176 -> 7568 | F2: =D2/E2 -> 0.30668605 | G2: 0.01 | H2: 176 | I2: =C2&B2&A2 -> 1ABBTemara | J2: =H2/F2/100 -> 5.7387678
A3: Temara | B3: Leclanché | C3: 1 | D3: 1108 | E3: =43*176 -> 7568 | F3: =D3/E3 -> 0.14640592 | G3: 0.01 | H3: 176 | I3: =C3&B3&A3 -> 1LeclanchéTemara | J3: =H3/F3/100 -> 12.021372
A4: Temara | B4: Soluscope | C4: 1 | D4: 255 | E4: =43*176 -> 7568 | F4: =D4/E4 -> 0.033694503 | G4: 0.01 | H4: 176 | I4: =C4&B4&A4 -> 1SoluscopeTemara | J4: =H4/F4/100 -> 52.234039
A5: Temara | B5: Alstom | C5: 1 | D5: 489 | E5: =43*176 -> 7568 | F5: =D5/E5 -> 0.064614165 | G5: 0.01 | H5: 176 | I5: =C5&B5&A5 -> 1AlstomTemara | J5: =H5/F5/100 -> 27.238609
A6: Temara | B6: Le reste | C6: 1 | D6: 2888 | E6: =43*176 -> 7568 | F6: =D6/E6 -> 0.38160677 | G6: 0.01 | H6: 176 | I6: =C6&B6&A6 -> 1Le resteTemara | J6: =H6/F6/100 -> 4.6120776
A7: Berrechid | B7: EDMI | C7: 3 | D7: 3000 | E7: 22000 | F7: =D7/E7 -> 0.13636364 | G7: 0.01 | H7: 176 | I7: =C7&B7&A7 -> 3EDMIBerrechid | J7: =H7/F7/100 -> 12.906667 | K7: 38 | L7: =K7/J7 -> 2.9442149
A8: Berrechid | B8: EMS | C8: 2 | D8: 720 | E8: 22000 | F8: =D8/E8 -> 0.032727273 | G8: 0.01 | H8: 176 | I8: =C8&B8&A8 -> 2EMSBerrechid | J8: =H8/F8/100 -> 53.777778
A9: Berrechid | B9: SOWEE | C9: 2 | D9: 320 | E9: 22000 | F9: =D9/E9 -> 0.014545455 | G9: 0.01 | H9: 176 | I9: =C9&B9&A9 -> 2SOWEEBerrechid | J9: =H9/F9/100 -> 121
A10: Berrechid | B10: Le reste | C10: 2 | D10: 1500 | E10: 22000 | F10: =D10/E10 -> 0.068181818 | G10: 0.01 | H10: 176 | I10: =C10&B10&A10 -> 2Le resteBerrechid | J10: =H10/F10/100 -> 25.813333

Sheet Arrêt par Département (2)
A2: Semaine | B2: (Plusieurs éléments)
A4: Étiquettes de lignes | B4: Somme de Durée en :H
A5: MAINTENANCE | B5: 76.783333
A6: BERRECHID | B6: 47.95
A7: Anomalie fonctionnelle produit | B7: 17.5
A8: Contrainte environnementale | B8: 8
A9: Instabilité équipement contrôle | B9: 8
A10: Panne curative machine | B10: 5.3333333
A11: Nettoyage / Entretien préventif | B11: 1.9166667
A12: Défaillance méca répétitive | B12: 1.85
A13: Défaillance réseau pneumatique | B13: 1.0166667
A14: Arrêt énergie nocturne | B14: 1
A15: Aménagement poste travail | B15: 1
A16: Panne pièce d'usure banc | B16: 0.91666667
... A26: Total général | B26: 76.783333

Sheet Arrêt par Département (3)
A1: Semaine | B1: (Plusieurs éléments)
A3: Étiquettes de lignes | B3: Somme de Durée en :H
A4: 2026-M01 | B4: 348.34
A5: TECHNIQUE | B5: 114.67333
A6: BERRECHID | B6: 44.183333
A7: TEMARA | B7: 70.49
A8: ORGANISATION | B8: 83.833333
A9: BERRECHID | B9: 3
A10: TEMARA | B10: 80.833333
A11: MAINTENANCE | B11: 76.783333
A12: BERRECHID | B12: 47.95
A13: TEMARA | B13: 28.833333
A14: SUPPLY | B14: 66.3
A15: BERRECHID | B15: 58.3
... A23: Total général | B23: 348.34

Sheet Arrêt par Département
A3: Étiquettes de lignes | B3: Somme de Durée en :H
A4: BERRECHID | B4: 160.18333
A5: 2026-S01 | B5: 17.366667
A6: 2026-S02 | B6: 82.25
A7: 2026-S03 | B7: 28.233333
A8: 2026-S04 | B8: 32.333333
A9: TEMARA | B9: 188.15667
A10: 2026-S02 | B10: 72.336667
A11: 2026-S03 | B11: 59.153333
A12: 2026-S04 | B12: 56.666667
A13: Total général | B13: 348.34

Sheet Arrêt en H Maroc
A1: Client | B1: (Plusieurs éléments)
A2: Bâtiment | B2: (Tous)
A4: Somme de Durée en :H | B4: Étiquettes de colonnes
A5: Étiquettes de lignes | B5: TECHNIQUE | C5: SUPPLY | D5: MAINTENANCE | E5: ORGANISATION | F5: IT | G5: FORMATION | H5: PRODUCTION | I5: ACHAT | J5: Total général
A6: 2026-S04 | B6: 19.5 | C6: 10.416667 | D6: 1.9166667 | E6: 36.166667 | F6: 4.5 | I6: 1 | J6: 73.5
A7: 2026-S03 | B7: 48.973333 | C7: 6.1666667 | D7: 10.58 | G7: 0.75 | J7: 66.47
A8: 2026-S02 | B8: 27.833333 | C8: 41.716667 | D8: 35.02 | E8: 37.666667 | F8: 0.5 | J8: 142.73667
A9: 2026-S01 | B9: 17.366667 | J9: 17.366667
A10: 2025-S53 | B10: 22.453333 | C10: 10.81 | D10: 3.6666667 | J10: 36.93
A11: 2025-S52 | B11: 23.41 | C11: 30.533333 | D11: 30.566667 | G11: 2.5 | H11: 1 | J11: 88.01
A12: Total général | B12: 159.53667 | C12: 99.643333 | D12: 81.75 | E12: 73.833333 | F12: 5 | G12: 3.25 | H12: 1 | I12: 1 | J12: 425.01333

Sheet Arrêt en Productivité Maroc
A2: Somme de Impact Productivité par client | B2: Étiquettes de colonnes
A3: Étiquettes de lignes | B3: MAINTENANCE | C3: SUPPLY | D3: TECHNIQUE | E3: IT | F3: FORMATION | G3: PRODUCTION | H3: Total général
A4: 2025-S53 | D4: 0.002776343 | H4: 0.002776343
A5: 2025-S52 | B5: 0.046270038 | C5: 0.023657025 | D5: 0.015748967 | F5: 0.0019369835 | G5: 0.00077479339 | H5: 0.088387807
A6: 2025-S51 | B6: 0.0017425344 | D6: 0.015538912 | E6: 0.010309995 | H6: 0.027591441
A7: 2025-S50 | B7: 0.019842068 | H7: 0.019842068
A8: 2025-S49 | B8: 0.010455206 | C8: 0.049079257 | H8: 0.059534463
A9: Total général | B9: 0.078309847 | C9: 0.072736282 | D9: 0.034064222 | E9: 0.010309995 | F9: 0.0019369835 | G9: 0.00077479339 | H9: 0.19813212

Sheet Arrêt en Productivité par site
A2: Somme de Impact Productivité par client | B2: Étiquettes de colonnes
A3: Étiquettes de lignes | B3: MAINTENANCE | C3: SUPPLY | D3: TECHNIQUE | E3: IT | F3: FORMATION | G3: PRODUCTION | H3: Total général
A4: TEMARA | B4: 0.07394776 | C4: 0.049079257 | D4: 0.015538912 | E4: 0.010309995 | H4: 0.14887592
A5: 2025-S52 | B5: 0.041907951 | H5: 0.041907951
A6: 2025-S51 | B6: 0.0017425344 | D6: 0.015538912 | E6: 0.010309995 | H6: 0.027591441
A7: 2025-S50 | B7: 0.019842068 | H7: 0.019842068
A8: 2025-S49 | B8: 0.010455206 | C8: 0.049079257 | H8: 0.059534463
A9: BERRECHID | B9: 0.0043620868 | C9: 0.023657025 | D9: 0.01852531 | F9: 0.0019369835 | G9: 0.00077479339 | H9: 0.049256198
A10: 2025-S53 | D10: 0.002776343 | H10: 0.002776343
A11: 2025-S52 | B11: 0.0043620868 | C11: 0.023657025 | D11: 0.015748967 | F11: 0.0019369835 | G11: 0.00077479339 | H11: 0.046479855
A12: Total général | B12: 0.078309847 | C12: 0.072736282 | D12: 0.034064222 | E12: 0.010309995 | F12: 0.0019369835 | G12: 0.00077479339 | H12: 0.19813212

Sheet Liste figée
A1: Matin | B1: Berrechid | C1: Bât A | D1: Oumaima
A2: APM | B2: Témara | C2: Bât B | D2: Salah
A3: Nuit | D3: Tarik
A4: Normale | D4: Ismail
D5: Latifa
D6: Rajaa
A7: APM | D7: Hanane
A8: Matin | D8: Nabil
A9: APM | D9: Khadim
A10: Normale | D10: Knidar
A11: Matin | D11: Mounir
A12: Normale | D12: Anssim
D13: Aziza
D14: Adel
D15: Meryem
D16: Nait Aiss
D17: Toufiq
D18: Dahab
D19: Badia
D20: Anass
D21: Samira

Sheet Arret hebdo par Batiment
A1: Année | B1: 2026
A3: Somme de Durée en :H | B3: Étiquettes de colonnes
A4: Étiquettes de lignes | B4: Bât A | C4: Bât B | D4: TEM | E4: Total général
A5: BERRECHID | B5: 118.98333 | C5: 62.2 | E5: 181.18333
A6: 2026-S01 | C6: 17.366667 | E6: 17.366667
A7: 2026-S02 | B7: 43.066667 | C7: 39.183333 | E7: 82.25
A8: 2026-S03 | B8: 26.083333 | C8: 2.15 | E8: 28.233333
A9: 2026-S04 | B9: 28.833333 | C9: 3.5 | E9: 32.333333
A10: 2026-S05 | B10: 21 | E10: 21
A11: TEMARA | D11: 212.15667 | E11: 212.15667
A12: 2026-S02 | D12: 72.336667 | E12: 72.336667
A13: 2026-S03 | D13: 59.153333 | E13: 59.153333
A14: 2026-S04 | D14: 56.666667 | E14: 56.666667
A15: 2026-S05 | D15: 24 | E15: 24
A16: Total général | B16: 118.98333 | C16: 62.2 | D16: 212.15667 | E16: 393.34

Sheet Arret hebdo % maroc
A1: Année | B1: 2026
A3: Étiquettes de lignes | B3: Somme de Impact Productivité par client
A4: BERRECHID | B4: 0.11988378
A5: 2026-S01 | B5: 0.013455579
A6: 2026-S02 | B6: 0.061145403
A7: 2026-S03 | B7: 0.015127841
A8: 2026-S04 | B8: 0.01902376
A9: 2026-S05 | B9: 0.011131198
A10: TEMARA | B10: 0.34710115
A11: 2026-S02 | B11: 0.1158687
A12: 2026-S03 | B12: 0.097647906
A13: 2026-S04 | B13: 0.091763716
A14: 2026-S05 | B14: 0.041820825
A15: Total général | B15: 0.46698493

Sheet Arret hebdo maroc
A1: Année | B1: 2026
A3: Étiquettes de lignes | B3: Somme de Durée en :H
A4: BERRECHID | B4: 181.18333
A5: 2026-S01 | B5: 17.366667
A6: 2026-S02 | B6: 82.25
A7: 2026-S03 | B7: 28.233333
A8: 2026-S04 | B8: 32.333333
A9: 2026-S05 | B9: 21
A10: TEMARA | B10: 212.15667
A11: 2026-S02 | B11: 72.336667
A12: 2026-S03 | B12: 59.153333
A13: 2026-S04 | B13: 56.666667
A14: 2026-S05 | B14: 24
A15: Total général | B15: 393.34

Sheet Arret hebdo par service
A2: Année | B2: 2026
A3: Site | B3: BERRECHID
A5: Somme de Durée en :H | B5: Étiquettes de colonnes
A6: Étiquettes de lignes | B6: Bât A | C6: Bât B | D6: Total général
A7: 2026-S03 | B7: 26.083333 | C7: 2.15 | D7: 28.233333
A8: MAINTENANCE | B8: 16.833333 | D8: 16.833333
A9: SUPPLY | B9: 6.1666667 | D9: 6.1666667
A10: TECHNIQUE | B10: 2.3333333 | C10: 2.15 | D10: 4.4833333
A11: FORMATION | B11: 0.75 | D11: 0.75
A12: 2026-S04 | B12: 28.833333 | C12: 3.5 | D12: 32.333333
A13: MAINTENANCE | B13: 12.916667 | D13: 12.916667
A14: SUPPLY | B14: 10.416667 | D14: 10.416667
A15: IT | B15: 1 | C15: 3.5 | D15: 4.5
A16: ORGANISATION | B16: 3 | D16: 3
A17: ACHAT | B17: 1 | D17: 1
A18: TECHNIQUE | B18: 0.5 | D18: 0.5
A19: Total général | B19: 54.916667 | C19: 5.65 | D19: 60.566667

Sheet Feuil2
A2: Site | B2: Temara
A4: Somme de Durée en :H | B4: Semaine
A5: Client | B5: 2026-S03 | C5: 2026-S04 | D5: Total général
A6: ABB | B6: 55.653333 | C6: 52.166667 | D6: 107.82
A7: Soluscope | B7: 3.5 | D7: 3.5
A8: Total général | B8: 59.153333 | C8: 52.166667 | D8: 111.32
